<?xml version="1.0" ?>
<!-- =================================================================================== -->
<!-- |    This document was autogenerated by xacro from phantomX_model.xacro           | -->
<!-- |    EDITING THIS FILE BY HAND IS NOT RECOMMENDED                                 | -->
<!-- =================================================================================== -->
<robot name="PhantomX" xmlns:xacro="http://ros.org/wiki/xacro">
  <gazebo>
    <plugin filename="libgazebo_ros_control.so" name="gazebo_ros_control">
      <robotNamespace>/PhantomX</robotNamespace>
    </plugin>
  </gazebo>
  <link name="base_link"/>
  <joint name="base_joint" type="fixed">
    <parent link="base_link"/>
    <child link="body_link"/>
    <origin rpy="0.0 0.0 0.0" xyz="0.0 0.0 0.0"/>
  </joint>
  <link name="body_link">
    <visual>
      <origin rpy="0.0 0.0 0.0" xyz="0.0 0.0 0.0"/>
      <geometry>
        <mesh filename="package://phantom_description/meshes/phantomX/body.stl" scale="0.001 0.001 0.001"/>
      </geometry>
      <material name="">
        <color rgba="0.7 0.7 0.7 1"/>
      </material>
    </visual>
    <collision>
      <origin rpy="0.0 0.0 0.0" xyz="0.0 0.0 0.0"/>
      <geometry>
        <mesh filename="package://phantom_description/meshes/phantomX/body.stl" scale="0.001 0.001 0.001"/>
      </geometry>
      <material name="">
        <color rgba="0.7 0.7 0.7 1"/>
      </material>
    </collision>
    <inertial>
      <origin rpy="0.0 0.0 0.0" xyz="0.0 0.0 0.0"/>
      <mass value="0.00001"/>
      <inertia ixx="1.0" ixy="0.0" ixz="0.0" iyy="1.0" iyz="0.0" izz="1.0"/>
    </inertial>
  </link>
  <gazebo reference="body_link">
    <material>Gazebo/DarkGrey</material>
  </gazebo>
  <!-- Head Pan and Tilt properties -->
  <joint name="head_pan_joint" type="revolute">
    <parent link="body_link"/>
    <child link="head_pan_link"/>
    <axis xyz="0.0 0.0 1.0"/>
    <origin xyz="0.145 0.0 0.080"/>
    <limit effort="10000" lower="-3.14" upper="3.14" velocity="100"/>
  </joint>
  <link name="head_pan_link">
    <inertial>
      <origin rpy="0.0 0.0 0.0" xyz="0.0 0.0 0.0"/>
      <mass value="0.00001"/>
      <inertia ixx="1.0" ixy="0.0" ixz="0.0" iyy="1.0" iyz="0.0" izz="1.0"/>
    </inertial>
  </link>
  <joint name="head_tilt_joint" type="revolute">
    <parent link="head_pan_link"/>
    <child link="head_tilt_link"/>
    <axis xyz="0.0 1.0 0.0"/>
    <origin xyz="0.0 0.0 0.020"/>
    <limit effort="10000" lower="-3.14" upper="3.14" velocity="100"/>
  </joint>
  <link name="head_tilt_link">
    <inertial>
      <origin rpy="0.0 0.0 0.0" xyz="0.0 0.0 0.0"/>
      <mass value="0.00001"/>
      <inertia ixx="1.0" ixy="0.0" ixz="0.0" iyy="1.0" iyz="0.0" izz="1.0"/>
    </inertial>
  </link>
  <!-- Camera properties -->
  <joint name="camera_rgb_joint" type="fixed">
    <parent link="head_tilt_link"/>
    <child link="camera_rgb_optical_frame"/>
    <origin rpy="1.57079632679 3.14159265359 1.57079632679" xyz="0.0 0.0 0.0"/>
  </joint>
  <link name="camera_rgb_optical_frame">
    <inertial>
      <origin rpy="0.0 0.0 0.0" xyz="0.0 0.0 0.0"/>
      <mass value="0.00001"/>
      <inertia ixx="1.0" ixy="0.0" ixz="0.0" iyy="1.0" iyz="0.0" izz="1.0"/>
    </inertial>
  </link>
  <joint name="camera_depth_joint" type="fixed">
    <parent link="head_tilt_link"/>
    <child link="camera_depth_optical_frame"/>
    <origin rpy="1.57079632679 3.14159265359 1.57079632679" xyz="0.0 0.0 0.0"/>
  </joint>
  <link name="camera_depth_optical_frame">
    <inertial>
      <origin rpy="0.0 0.0 0.0" xyz="0.0 0.0 0.0"/>
      <mass value="0.00001"/>
      <inertia ixx="1.0" ixy="0.0" ixz="0.0" iyy="1.0" iyz="0.0" izz="1.0"/>
    </inertial>
  </link>
  <joint name="camera_depth_frame" type="fixed">
    <parent link="head_tilt_link"/>
    <child link="camera_depth_frame_link"/>
    <origin xyz="0.0 0.0 0.0"/>
  </joint>
  <link name="camera_depth_frame_link">
    <inertial>
      <origin rpy="0.0 0.0 0.0" xyz="0.0 0.0 0.0"/>
      <mass value="0.00001"/>
      <inertia ixx="1.0" ixy="0.0" ixz="0.0" iyy="1.0" iyz="0.0" izz="1.0"/>
    </inertial>
  </link>
  <!-- IMU properties -->
  <joint name="imu_joint" type="fixed">
    <parent link="base_link"/>
    <child link="imu_link"/>
    <origin rpy="0.0 0.0 0.0" xyz="0.0 0.0 0.0"/>
  </joint>
  <link name="imu_link">
    <inertial>
      <origin rpy="0.0 0.0 0.0" xyz="0.0 0.0 0.0"/>
      <mass value="0.00001"/>
      <inertia ixx="1.0" ixy="0.0" ixz="0.0" iyy="1.0" iyz="0.0" izz="1.0"/>
    </inertial>
  </link>
  <!-- leg position -->
  <joint name="leg_center_joint_RR" type="fixed">
    <origin rpy="0.0 0.0 0.0" xyz="-0.12 -0.06 0.0"/>
    <parent link="body_link"/>
    <child link="leg_center_RR"/>
  </joint>
  <link name="leg_center_RR">
    <inertial>
      <origin rpy="0.0 0.0 0.0" xyz="0.0 0.0 0.0"/>
      <mass value="0.00001"/>
      <inertia ixx="1.0" ixy="0.0" ixz="0.0" iyy="1.0" iyz="0.0" izz="1.0"/>
    </inertial>
  </link>
  <!-- coxa -->
  <joint name="coxa_joint_RR" type="revolute">
    <origin rpy="0.0 0.0 -2.35619449019" xyz="0.0 0.0 0.0"/>
    <parent link="leg_center_RR"/>
    <child link="coxa_RR"/>
    <axis xyz="0.0 0.0 1.0"/>
    <limit effort="6.0" lower="-3.14" upper="3.14" velocity="0.524"/>
  </joint>
  <transmission name="coxa_transmission_RR">
    <type>transmission_interface/SimpleTransmission</type>
    <joint name="coxa_joint_RR">
      <hardwareInterface>EffortJointInterface</hardwareInterface>
    </joint>
    <actuator name="coxa_motor_RR">
      <hardwareInterface>EffortJointInterface</hardwareInterface>
      <mechanicalReduction>1</mechanicalReduction>
    </actuator>
  </transmission>
  <link name="coxa_RR">
    <visual>
      <origin rpy="0.0 0.0 0.0" xyz="0.0 0.0 0.0"/>
      <geometry>
        <mesh filename="package://phantom_description/meshes/phantomX/coxa.stl" scale="0.001 0.001 0.001"/>
      </geometry>
      <material name="">
        <color rgba="0.7 0.7 0.7 1"/>
      </material>
    </visual>
    <collision>
      <origin rpy="0.0 0.0 0.0" xyz="0.0 0.0 0.0"/>
      <geometry>
        <mesh filename="package://phantom_description/meshes/phantomX/coxa.stl" scale="0.001 0.001 0.001"/>
      </geometry>
      <material name="">
        <color rgba="0.7 0.7 0.7 1"/>
      </material>
    </collision>
    <inertial>
      <origin rpy="0.0 0.0 0.0" xyz="0.0 0.0 0.0"/>
      <mass value="0.00001"/>
      <inertia ixx="1.0" ixy="0.0" ixz="0.0" iyy="1.0" iyz="0.0" izz="1.0"/>
    </inertial>
  </link>
  <gazebo reference="coxa_RR">
    <material>Gazebo/DarkGrey</material>
  </gazebo>
  <!-- femur -->
  <joint name="femur_joint_RR" type="revolute">
    <origin rpy="-1.57079632679 1.57079632679 0.0" xyz="0.052 0.0 0.0"/>
    <parent link="coxa_RR"/>
    <child link="femur_RR"/>
    <axis xyz="0.0 0.0 -1"/>
    <limit effort="6.0" lower="-3.14" upper="3.14" velocity="0.524"/>
  </joint>
  <transmission name="femur_transmission_RR">
    <type>transmission_interface/SimpleTransmission</type>
    <joint name="femur_joint_RR">
      <hardwareInterface>EffortJointInterface</hardwareInterface>
    </joint>
    <actuator name="femur_motor_RR">
      <hardwareInterface>EffortJointInterface</hardwareInterface>
      <mechanicalReduction>1</mechanicalReduction>
    </actuator>
  </transmission>
  <link name="femur_RR">
    <visual>
      <origin rpy="0.0 0.0 0.0" xyz="0.0 0.0 0.0"/>
      <geometry>
        <mesh filename="package://phantom_description/meshes/phantomX/femur.stl" scale="0.001 0.001 0.001"/>
      </geometry>
      <material name="">
        <color rgba="0.7 0.7 0.7 1"/>
      </material>
    </visual>
    <collision>
      <origin rpy="0.0 0.0 0.0" xyz="0.0 0.0 0.0"/>
      <geometry>
        <mesh filename="package://phantom_description/meshes/phantomX/femur.stl" scale="0.001 0.001 0.001"/>
      </geometry>
      <material name="">
        <color rgba="0.7 0.7 0.7 1"/>
      </material>
    </collision>
    <inertial>
      <origin rpy="0.0 0.0 0.0" xyz="0.0 0.0 0.0"/>
      <mass value="0.00001"/>
      <inertia ixx="1.0" ixy="0.0" ixz="0.0" iyy="1.0" iyz="0.0" izz="1.0"/>
    </inertial>
  </link>
  <gazebo reference="femur_RR">
    <material>Gazebo/DarkGrey</material>
  </gazebo>
  <!-- tibia -->
  <joint name="tibia_joint_RR" type="revolute">
    <origin rpy="3.14159265359 0.0 0.0" xyz="0.0 -0.065 0.0"/>
    <parent link="femur_RR"/>
    <child link="tibia_RR"/>
    <axis xyz="0.0 0.0 1"/>
    <limit effort="6.0" lower="-3.14" upper="3.14" velocity="0.524"/>
  </joint>
  <transmission name="tibia_transmission_RR">
    <type>transmission_interface/SimpleTransmission</type>
    <joint name="tibia_joint_RR">
      <hardwareInterface>EffortJointInterface</hardwareInterface>
    </joint>
    <actuator name="tibia_motor_RR">
      <hardwareInterface>EffortJointInterface</hardwareInterface>
      <mechanicalReduction>1</mechanicalReduction>
    </actuator>
  </transmission>
  <link name="tibia_RR">
    <visual>
      <origin rpy="0.0 0.0 0.0" xyz="0.0 0.0 0.0"/>
      <geometry>
        <mesh filename="package://phantom_description/meshes/phantomX/tibia.stl" scale="0.001 0.001 0.001"/>
      </geometry>
      <material name="">
        <color rgba="0.7 0.7 0.7 1"/>
      </material>
    </visual>
    <collision>
      <origin rpy="0.0 0.0 0.0" xyz="0.0 0.0 0.0"/>
      <geometry>
        <mesh filename="package://phantom_description/meshes/phantomX/tibia.stl" scale="0.001 0.001 0.001"/>
      </geometry>
      <material name="">
        <color rgba="0.7 0.7 0.7 1"/>
      </material>
    </collision>
    <inertial>
      <origin rpy="0.0 0.0 0.0" xyz="0.0 0.0 0.0"/>
      <mass value="0.00001"/>
      <inertia ixx="1.0" ixy="0.0" ixz="0.0" iyy="1.0" iyz="0.0" izz="1.0"/>
    </inertial>
  </link>
  <gazebo reference="tibia_RR">
    <material>Gazebo/DarkGrey</material>
  </gazebo>
  <!-- leg position -->
  <joint name="leg_center_joint_RM" type="fixed">
    <origin rpy="0.0 0.0 0.0" xyz="0.0 -0.1 0.0"/>
    <parent link="body_link"/>
    <child link="leg_center_RM"/>
  </joint>
  <link name="leg_center_RM">
    <inertial>
      <origin rpy="0.0 0.0 0.0" xyz="0.0 0.0 0.0"/>
      <mass value="0.00001"/>
      <inertia ixx="1.0" ixy="0.0" ixz="0.0" iyy="1.0" iyz="0.0" izz="1.0"/>
    </inertial>
  </link>
  <!-- coxa -->
  <joint name="coxa_joint_RM" type="revolute">
    <origin rpy="0.0 0.0 -1.57079632679" xyz="0.0 0.0 0.0"/>
    <parent link="leg_center_RM"/>
    <child link="coxa_RM"/>
    <axis xyz="0.0 0.0 1.0"/>
    <limit effort="6.0" lower="-3.14" upper="3.14" velocity="0.524"/>
  </joint>
  <transmission name="coxa_transmission_RM">
    <type>transmission_interface/SimpleTransmission</type>
    <joint name="coxa_joint_RM">
      <hardwareInterface>EffortJointInterface</hardwareInterface>
    </joint>
    <actuator name="coxa_motor_RM">
      <hardwareInterface>EffortJointInterface</hardwareInterface>
      <mechanicalReduction>1</mechanicalReduction>
    </actuator>
  </transmission>
  <link name="coxa_RM">
    <visual>
      <origin rpy="0.0 0.0 0.0" xyz="0.0 0.0 0.0"/>
      <geometry>
        <mesh filename="package://phantom_description/meshes/phantomX/coxa.stl" scale="0.001 0.001 0.001"/>
      </geometry>
      <material name="">
        <color rgba="0.7 0.7 0.7 1"/>
      </material>
    </visual>
    <collision>
      <origin rpy="0.0 0.0 0.0" xyz="0.0 0.0 0.0"/>
      <geometry>
        <mesh filename="package://phantom_description/meshes/phantomX/coxa.stl" scale="0.001 0.001 0.001"/>
      </geometry>
      <material name="">
        <color rgba="0.7 0.7 0.7 1"/>
      </material>
    </collision>
    <inertial>
      <origin rpy="0.0 0.0 0.0" xyz="0.0 0.0 0.0"/>
      <mass value="0.00001"/>
      <inertia ixx="1.0" ixy="0.0" ixz="0.0" iyy="1.0" iyz="0.0" izz="1.0"/>
    </inertial>
  </link>
  <gazebo reference="coxa_RM">
    <material>Gazebo/DarkGrey</material>
  </gazebo>
  <!-- femur -->
  <joint name="femur_joint_RM" type="revolute">
    <origin rpy="-1.57079632679 1.57079632679 0.0" xyz="0.052 0.0 0.0"/>
    <parent link="coxa_RM"/>
    <child link="femur_RM"/>
    <axis xyz="0.0 0.0 -1"/>
    <limit effort="6.0" lower="-3.14" upper="3.14" velocity="0.524"/>
  </joint>
  <transmission name="femur_transmission_RM">
    <type>transmission_interface/SimpleTransmission</type>
    <joint name="femur_joint_RM">
      <hardwareInterface>EffortJointInterface</hardwareInterface>
    </joint>
    <actuator name="femur_motor_RM">
      <hardwareInterface>EffortJointInterface</hardwareInterface>
      <mechanicalReduction>1</mechanicalReduction>
    </actuator>
  </transmission>
  <link name="femur_RM">
    <visual>
      <origin rpy="0.0 0.0 0.0" xyz="0.0 0.0 0.0"/>
      <geometry>
        <mesh filename="package://phantom_description/meshes/phantomX/femur.stl" scale="0.001 0.001 0.001"/>
      </geometry>
      <material name="">
        <color rgba="0.7 0.7 0.7 1"/>
      </material>
    </visual>
    <collision>
      <origin rpy="0.0 0.0 0.0" xyz="0.0 0.0 0.0"/>
      <geometry>
        <mesh filename="package://phantom_description/meshes/phantomX/femur.stl" scale="0.001 0.001 0.001"/>
      </geometry>
      <material name="">
        <color rgba="0.7 0.7 0.7 1"/>
      </material>
    </collision>
    <inertial>
      <origin rpy="0.0 0.0 0.0" xyz="0.0 0.0 0.0"/>
      <mass value="0.00001"/>
      <inertia ixx="1.0" ixy="0.0" ixz="0.0" iyy="1.0" iyz="0.0" izz="1.0"/>
    </inertial>
  </link>
  <gazebo reference="femur_RM">
    <material>Gazebo/DarkGrey</material>
  </gazebo>
  <!-- tibia -->
  <joint name="tibia_joint_RM" type="revolute">
    <origin rpy="3.14159265 0.0 0.0" xyz="0.0 -0.065 0.0"/>
    <parent link="femur_RM"/>
    <child link="tibia_RM"/>
    <axis xyz="0.0 0.0 1"/>
    <limit effort="6.0" lower="-3.14" upper="3.14" velocity="0.524"/>
  </joint>
  <transmission name="tibia_transmission_RM">
    <type>transmission_interface/SimpleTransmission</type>
    <joint name="tibia_joint_RM">
      <hardwareInterface>EffortJointInterface</hardwareInterface>
    </joint>
    <actuator name="tibia_motor_RM">
      <hardwareInterface>EffortJointInterface</hardwareInterface>
      <mechanicalReduction>1</mechanicalReduction>
    </actuator>
  </transmission>
  <link name="tibia_RM">
    <visual>
      <origin rpy="0.0 0.0 0.0" xyz="0.0 0.0 0.0"/>
      <geometry>
        <mesh filename="package://phantom_description/meshes/phantomX/tibia.stl" scale="0.001 0.001 0.001"/>
      </geometry>
      <material name="">
        <color rgba="0.7 0.7 0.7 1"/>
      </material>
    </visual>
    <collision>
      <origin rpy="0.0 0.0 0.0" xyz="0.0 0.0 0.0"/>
      <geometry>
        <mesh filename="package://phantom_description/meshes/phantomX/tibia.stl" scale="0.001 0.001 0.001"/>
      </geometry>
      <material name="">
        <color rgba="0.7 0.7 0.7 1"/>
      </material>
    </collision>
    <inertial>
      <origin rpy="0.0 0.0 0.0" xyz="0.0 0.0 0.0"/>
      <mass value="0.00001"/>
      <inertia ixx="1.0" ixy="0.0" ixz="0.0" iyy="1.0" iyz="0.0" izz="1.0"/>
    </inertial>
  </link>
  <gazebo reference="tibia_RM">
    <material>Gazebo/DarkGrey</material>
  </gazebo>
  <!-- leg position -->
  <joint name="leg_center_joint_RF" type="fixed">
    <origin rpy="0.0 0.0 0.0" xyz="0.12 -0.06 0.0"/>
    <parent link="body_link"/>
    <child link="leg_center_RF"/>
  </joint>
  <link name="leg_center_RF">
    <inertial>
      <origin rpy="0.0 0.0 0.0" xyz="0.0 0.0 0.0"/>
      <mass value="0.00001"/>
      <inertia ixx="1.0" ixy="0.0" ixz="0.0" iyy="1.0" iyz="0.0" izz="1.0"/>
    </inertial>
  </link>
  <!-- coxa -->
  <joint name="coxa_joint_RF" type="revolute">
    <origin rpy="0.0 0.0 -0.785398163397" xyz="0.0 0.0 0.0"/>
    <parent link="leg_center_RF"/>
    <child link="coxa_RF"/>
    <axis xyz="0.0 0.0 1.0"/>
    <limit effort="6.0" lower="-3.14" upper="3.14" velocity="0.524"/>
  </joint>
  <transmission name="coxa_transmission_RF">
    <type>transmission_interface/SimpleTransmission</type>
    <joint name="coxa_joint_RF">
      <hardwareInterface>EffortJointInterface</hardwareInterface>
    </joint>
    <actuator name="coxa_motor_RF">
      <hardwareInterface>EffortJointInterface</hardwareInterface>
      <mechanicalReduction>1</mechanicalReduction>
    </actuator>
  </transmission>
  <link name="coxa_RF">
    <visual>
      <origin rpy="0.0 0.0 0.0" xyz="0.0 0.0 0.0"/>
      <geometry>
        <mesh filename="package://phantom_description/meshes/phantomX/coxa.stl" scale="0.001 0.001 0.001"/>
      </geometry>
      <material name="">
        <color rgba="0.7 0.7 0.7 1"/>
      </material>
    </visual>
    <collision>
      <origin rpy="0.0 0.0 0.0" xyz="0.0 0.0 0.0"/>
      <geometry>
        <mesh filename="package://phantom_description/meshes/phantomX/coxa.stl" scale="0.001 0.001 0.001"/>
      </geometry>
      <material name="">
        <color rgba="0.7 0.7 0.7 1"/>
      </material>
    </collision>
    <inertial>
      <origin rpy="0.0 0.0 0.0" xyz="0.0 0.0 0.0"/>
      <mass value="0.00001"/>
      <inertia ixx="1.0" ixy="0.0" ixz="0.0" iyy="1.0" iyz="0.0" izz="1.0"/>
    </inertial>
  </link>
  <gazebo reference="coxa_RF">
    <material>Gazebo/DarkGrey</material>
  </gazebo>
  <!-- femur -->
  <joint name="femur_joint_RF" type="revolute">
    <origin rpy="-1.57079632679 1.57079632679 0.0" xyz="0.052 0.0 0.0"/>
    <parent link="coxa_RF"/>
    <child link="femur_RF"/>
    <axis xyz="0.0 0.0 -1"/>
    <limit effort="6.0" lower="-3.14" upper="3.14" velocity="0.524"/>
  </joint>
  <transmission name="femur_transmission_RF">
    <type>transmission_interface/SimpleTransmission</type>
    <joint name="femur_joint_RF">
      <hardwareInterface>EffortJointInterface</hardwareInterface>
    </joint>
    <actuator name="femur_motor_RF">
      <hardwareInterface>EffortJointInterface</hardwareInterface>
      <mechanicalReduction>1</mechanicalReduction>
    </actuator>
  </transmission>
  <link name="femur_RF">
    <visual>
      <origin rpy="0.0 0.0 0.0" xyz="0.0 0.0 0.0"/>
      <geometry>
        <mesh filename="package://phantom_description/meshes/phantomX/femur.stl" scale="0.001 0.001 0.001"/>
      </geometry>
      <material name="">
        <color rgba="0.7 0.7 0.7 1"/>
      </material>
    </visual>
    <collision>
      <origin rpy="0.0 0.0 0.0" xyz="0.0 0.0 0.0"/>
      <geometry>
        <mesh filename="package://phantom_description/meshes/phantomX/femur.stl" scale="0.001 0.001 0.001"/>
      </geometry>
      <material name="">
        <color rgba="0.7 0.7 0.7 1"/>
      </material>
    </collision>
    <inertial>
      <origin rpy="0.0 0.0 0.0" xyz="0.0 0.0 0.0"/>
      <mass value="0.00001"/>
      <inertia ixx="1.0" ixy="0.0" ixz="0.0" iyy="1.0" iyz="0.0" izz="1.0"/>
    </inertial>
  </link>
  <gazebo reference="femur_RF">
    <material>Gazebo/DarkGrey</material>
  </gazebo>
  <!-- tibia -->
  <joint name="tibia_joint_RF" type="revolute">
    <origin rpy="3.14159265359 0.0 0.0" xyz="0.0 -0.065 0.0"/>
    <parent link="femur_RF"/>
    <child link="tibia_RF"/>
    <axis xyz="0.0 0.0 1"/>
    <limit effort="6.0" lower="-3.14" upper="3.14" velocity="0.524"/>
  </joint>
  <transmission name="tibia_transmission_RF">
    <type>transmission_interface/SimpleTransmission</type>
    <joint name="tibia_joint_RF">
      <hardwareInterface>EffortJointInterface</hardwareInterface>
    </joint>
    <actuator name="tibia_motor_RF">
      <hardwareInterface>EffortJointInterface</hardwareInterface>
      <mechanicalReduction>1</mechanicalReduction>
    </actuator>
  </transmission>
  <link name="tibia_RF">
    <visual>
      <origin rpy="0.0 0.0 0.0" xyz="0.0 0.0 0.0"/>
      <geometry>
        <mesh filename="package://phantom_description/meshes/phantomX/tibia.stl" scale="0.001 0.001 0.001"/>
      </geometry>
      <material name="">
        <color rgba="0.7 0.7 0.7 1"/>
      </material>
    </visual>
    <collision>
      <origin rpy="0.0 0.0 0.0" xyz="0.0 0.0 0.0"/>
      <geometry>
        <mesh filename="package://phantom_description/meshes/phantomX/tibia.stl" scale="0.001 0.001 0.001"/>
      </geometry>
      <material name="">
        <color rgba="0.7 0.7 0.7 1"/>
      </material>
    </collision>
    <inertial>
      <origin rpy="0.0 0.0 0.0" xyz="0.0 0.0 0.0"/>
      <mass value="0.00001"/>
      <inertia ixx="1.0" ixy="0.0" ixz="0.0" iyy="1.0" iyz="0.0" izz="1.0"/>
    </inertial>
  </link>
  <gazebo reference="tibia_RF">
    <material>Gazebo/DarkGrey</material>
  </gazebo>
  <!-- leg position -->
  <joint name="leg_center_joint_LR" type="fixed">
    <origin rpy="0.0 0.0 0.0" xyz="-0.12 0.06 0.0"/>
    <parent link="body_link"/>
    <child link="leg_center_LR"/>
  </joint>
  <link name="leg_center_LR">
    <inertial>
      <origin rpy="0.0 0.0 0.0" xyz="0.0 0.0 0.0"/>
      <mass value="0.00001"/>
      <inertia ixx="1.0" ixy="0.0" ixz="0.0" iyy="1.0" iyz="0.0" izz="1.0"/>
    </inertial>
  </link>
  <!-- coxa -->
  <joint name="coxa_joint_LR" type="revolute">
    <origin rpy="0.0 0.0 2.35619449019" xyz="0.0 0.0 0.0"/>
    <parent link="leg_center_LR"/>
    <child link="coxa_LR"/>
    <axis xyz="0.0 0.0 1.0"/>
    <limit effort="6.0" lower="-3.14" upper="3.14" velocity="0.524"/>
  </joint>
  <transmission name="coxa_transmission_LR">
    <type>transmission_interface/SimpleTransmission</type>
    <joint name="coxa_joint_LR">
      <hardwareInterface>EffortJointInterface</hardwareInterface>
    </joint>
    <actuator name="coxa_motor_LR">
      <hardwareInterface>EffortJointInterface</hardwareInterface>
      <mechanicalReduction>1</mechanicalReduction>
    </actuator>
  </transmission>
  <link name="coxa_LR">
    <visual>
      <origin rpy="0.0 0.0 0.0" xyz="0.0 0.0 0.0"/>
      <geometry>
        <mesh filename="package://phantom_description/meshes/phantomX/coxa.stl" scale="0.001 0.001 0.001"/>
      </geometry>
      <material name="">
        <color rgba="0.7 0.7 0.7 1"/>
      </material>
    </visual>
    <collision>
      <origin rpy="0.0 0.0 0.0" xyz="0.0 0.0 0.0"/>
      <geometry>
        <mesh filename="package://phantom_description/meshes/phantomX/coxa.stl" scale="0.001 0.001 0.001"/>
      </geometry>
      <material name="">
        <color rgba="0.7 0.7 0.7 1"/>
      </material>
    </collision>
    <inertial>
      <origin rpy="0.0 0.0 0.0" xyz="0.0 0.0 0.0"/>
      <mass value="0.00001"/>
      <inertia ixx="1.0" ixy="0.0" ixz="0.0" iyy="1.0" iyz="0.0" izz="1.0"/>
    </inertial>
  </link>
  <gazebo reference="coxa_LR">
    <material>Gazebo/DarkGrey</material>
  </gazebo>
  <!-- femur -->
  <joint name="femur_joint_LR" type="revolute">
    <origin rpy="-1.57079632679 1.57079632679 0.0" xyz="0.052 0.0 0.0"/>
    <parent link="coxa_LR"/>
    <child link="femur_LR"/>
    <axis xyz="0.0 0.0 1"/>
    <limit effort="6.0" lower="-3.14" upper="3.14" velocity="0.524"/>
  </joint>
  <transmission name="femur_transmission_LR">
    <type>transmission_interface/SimpleTransmission</type>
    <joint name="femur_joint_LR">
      <hardwareInterface>EffortJointInterface</hardwareInterface>
    </joint>
    <actuator name="femur_motor_LR">
      <hardwareInterface>EffortJointInterface</hardwareInterface>
      <mechanicalReduction>1</mechanicalReduction>
    </actuator>
  </transmission>
  <link name="femur_LR">
    <visual>
      <origin rpy="0.0 0.0 0.0" xyz="0.0 0.0 0.0"/>
      <geometry>
        <mesh filename="package://phantom_description/meshes/phantomX/femur.stl" scale="0.001 0.001 0.001"/>
      </geometry>
      <material name="">
        <color rgba="0.7 0.7 0.7 1"/>
      </material>
    </visual>
    <collision>
      <origin rpy="0.0 0.0 0.0" xyz="0.0 0.0 0.0"/>
      <geometry>
        <mesh filename="package://phantom_description/meshes/phantomX/femur.stl" scale="0.001 0.001 0.001"/>
      </geometry>
      <material name="">
        <color rgba="0.7 0.7 0.7 1"/>
      </material>
    </collision>
    <inertial>
      <origin rpy="0.0 0.0 0.0" xyz="0.0 0.0 0.0"/>
      <mass value="0.00001"/>
      <inertia ixx="1.0" ixy="0.0" ixz="0.0" iyy="1.0" iyz="0.0" izz="1.0"/>
    </inertial>
  </link>
  <gazebo reference="femur_LR">
    <material>Gazebo/DarkGrey</material>
  </gazebo>
  <!-- tibia -->
  <joint name="tibia_joint_LR" type="revolute">
    <origin rpy="3.14159265359 0.0 0.0" xyz="0.0 -0.065 0.0"/>
    <parent link="femur_LR"/>
    <child link="tibia_LR"/>
    <axis xyz="0.0 0.0 -1"/>
    <limit effort="6.0" lower="-3.14" upper="3.14" velocity="0.524"/>
  </joint>
  <transmission name="tibia_transmission_LR">
    <type>transmission_interface/SimpleTransmission</type>
    <joint name="tibia_joint_LR">
      <hardwareInterface>EffortJointInterface</hardwareInterface>
    </joint>
    <actuator name="tibia_motor_LR">
      <hardwareInterface>EffortJointInterface</hardwareInterface>
      <mechanicalReduction>1</mechanicalReduction>
    </actuator>
  </transmission>
  <link name="tibia_LR">
    <visual>
      <origin rpy="0.0 0.0 0.0" xyz="0.0 0.0 0.0"/>
      <geometry>
        <mesh filename="package://phantom_description/meshes/phantomX/tibia.stl" scale="0.001 0.001 0.001"/>
      </geometry>
      <material name="">
        <color rgba="0.7 0.7 0.7 1"/>
      </material>
    </visual>
    <collision>
      <origin rpy="0.0 0.0 0.0" xyz="0.0 0.0 0.0"/>
      <geometry>
        <mesh filename="package://phantom_description/meshes/phantomX/tibia.stl" scale="0.001 0.001 0.001"/>
      </geometry>
      <material name="">
        <color rgba="0.7 0.7 0.7 1"/>
      </material>
    </collision>
    <inertial>
      <origin rpy="0.0 0.0 0.0" xyz="0.0 0.0 0.0"/>
      <mass value="0.00001"/>
      <inertia ixx="1.0" ixy="0.0" ixz="0.0" iyy="1.0" iyz="0.0" izz="1.0"/>
    </inertial>
  </link>
  <gazebo reference="tibia_LR">
    <material>Gazebo/DarkGrey</material>
  </gazebo>
  <!-- leg position -->
  <joint name="leg_center_joint_LM" type="fixed">
    <origin rpy="0.0 0.0 0.0" xyz="0.0 0.1 0.0"/>
    <parent link="body_link"/>
    <child link="leg_center_LM"/>
  </joint>
  <link name="leg_center_LM">
    <inertial>
      <origin rpy="0.0 0.0 0.0" xyz="0.0 0.0 0.0"/>
      <mass value="0.00001"/>
      <inertia ixx="1.0" ixy="0.0" ixz="0.0" iyy="1.0" iyz="0.0" izz="1.0"/>
    </inertial>
  </link>
  <!-- coxa -->
  <joint name="coxa_joint_LM" type="revolute">
    <origin rpy="0.0 0.0 1.57079632679" xyz="0.0 0.0 0.0"/>
    <parent link="leg_center_LM"/>
    <child link="coxa_LM"/>
    <axis xyz="0.0 0.0 1.0"/>
    <limit effort="6.0" lower="-3.14" upper="3.14" velocity="0.524"/>
  </joint>
  <transmission name="coxa_transmission_LM">
    <type>transmission_interface/SimpleTransmission</type>
    <joint name="coxa_joint_LM">
      <hardwareInterface>EffortJointInterface</hardwareInterface>
    </joint>
    <actuator name="coxa_motor_LM">
      <hardwareInterface>EffortJointInterface</hardwareInterface>
      <mechanicalReduction>1</mechanicalReduction>
    </actuator>
  </transmission>
  <link name="coxa_LM">
    <visual>
      <origin rpy="0.0 0.0 0.0" xyz="0.0 0.0 0.0"/>
      <geometry>
        <mesh filename="package://phantom_description/meshes/phantomX/coxa.stl" scale="0.001 0.001 0.001"/>
      </geometry>
      <material name="">
        <color rgba="0.7 0.7 0.7 1"/>
      </material>
    </visual>
    <collision>
      <origin rpy="0.0 0.0 0.0" xyz="0.0 0.0 0.0"/>
      <geometry>
        <mesh filename="package://phantom_description/meshes/phantomX/coxa.stl" scale="0.001 0.001 0.001"/>
      </geometry>
      <material name="">
        <color rgba="0.7 0.7 0.7 1"/>
      </material>
    </collision>
    <inertial>
      <origin rpy="0.0 0.0 0.0" xyz="0.0 0.0 0.0"/>
      <mass value="0.00001"/>
      <inertia ixx="1.0" ixy="0.0" ixz="0.0" iyy="1.0" iyz="0.0" izz="1.0"/>
    </inertial>
  </link>
  <gazebo reference="coxa_LM">
    <material>Gazebo/DarkGrey</material>
  </gazebo>
  <!-- femur -->
  <joint name="femur_joint_LM" type="revolute">
    <origin rpy="-1.57079632679 1.57079632679 0.0" xyz="0.052 0.0 0.0"/>
    <parent link="coxa_LM"/>
    <child link="femur_LM"/>
    <axis xyz="0.0 0.0 1"/>
    <limit effort="6.0" lower="-3.14" upper="3.14" velocity="0.524"/>
  </joint>
  <transmission name="femur_transmission_LM">
    <type>transmission_interface/SimpleTransmission</type>
    <joint name="femur_joint_LM">
      <hardwareInterface>EffortJointInterface</hardwareInterface>
    </joint>
    <actuator name="femur_motor_LM">
      <hardwareInterface>EffortJointInterface</hardwareInterface>
      <mechanicalReduction>1</mechanicalReduction>
    </actuator>
  </transmission>
  <link name="femur_LM">
    <visual>
      <origin rpy="0.0 0.0 0.0" xyz="0.0 0.0 0.0"/>
      <geometry>
        <mesh filename="package://phantom_description/meshes/phantomX/femur.stl" scale="0.001 0.001 0.001"/>
      </geometry>
      <material name="">
        <color rgba="0.7 0.7 0.7 1"/>
      </material>
    </visual>
    <collision>
      <origin rpy="0.0 0.0 0.0" xyz="0.0 0.0 0.0"/>
      <geometry>
        <mesh filename="package://phantom_description/meshes/phantomX/femur.stl" scale="0.001 0.001 0.001"/>
      </geometry>
      <material name="">
        <color rgba="0.7 0.7 0.7 1"/>
      </material>
    </collision>
    <inertial>
      <origin rpy="0.0 0.0 0.0" xyz="0.0 0.0 0.0"/>
      <mass value="0.00001"/>
      <inertia ixx="1.0" ixy="0.0" ixz="0.0" iyy="1.0" iyz="0.0" izz="1.0"/>
    </inertial>
  </link>
  <gazebo reference="femur_LM">
    <material>Gazebo/DarkGrey</material>
  </gazebo>
  <!-- tibia -->
  <joint name="tibia_joint_LM" type="revolute">
    <origin rpy="3.14159265359 0.0 0.0" xyz="0.0 -0.065 0.0"/>
    <parent link="femur_LM"/>
    <child link="tibia_LM"/>
    <axis xyz="0.0 0.0 -1"/>
    <limit effort="6.0" lower="-3.14" upper="3.14" velocity="0.524"/>
  </joint>
  <transmission name="tibia_transmission_LM">
    <type>transmission_interface/SimpleTransmission</type>
    <joint name="tibia_joint_LM">
      <hardwareInterface>EffortJointInterface</hardwareInterface>
    </joint>
    <actuator name="tibia_motor_LM">
      <hardwareInterface>EffortJointInterface</hardwareInterface>
      <mechanicalReduction>1</mechanicalReduction>
    </actuator>
  </transmission>
  <link name="tibia_LM">
    <visual>
      <origin rpy="0.0 0.0 0.0" xyz="0.0 0.0 0.0"/>
      <geometry>
        <mesh filename="package://phantom_description/meshes/phantomX/tibia.stl" scale="0.001 0.001 0.001"/>
      </geometry>
      <material name="">
        <color rgba="0.7 0.7 0.7 1"/>
      </material>
    </visual>
    <collision>
      <origin rpy="0.0 0.0 0.0" xyz="0.0 0.0 0.0"/>
      <geometry>
        <mesh filename="package://phantom_description/meshes/phantomX/tibia.stl" scale="0.001 0.001 0.001"/>
      </geometry>
      <material name="">
        <color rgba="0.7 0.7 0.7 1"/>
      </material>
    </collision>
    <inertial>
      <origin rpy="0.0 0.0 0.0" xyz="0.0 0.0 0.0"/>
      <mass value="0.00001"/>
      <inertia ixx="1.0" ixy="0.0" ixz="0.0" iyy="1.0" iyz="0.0" izz="1.0"/>
    </inertial>
  </link>
  <gazebo reference="tibia_LM">
    <material>Gazebo/DarkGrey</material>
  </gazebo>
  <!-- leg position -->
  <joint name="leg_center_joint_LF" type="fixed">
    <origin rpy="0.0 0.0 0.0" xyz="0.12 0.06 0.0"/>
    <parent link="body_link"/>
    <child link="leg_center_LF"/>
  </joint>
  <link name="leg_center_LF">
    <inertial>
      <origin rpy="0.0 0.0 0.0" xyz="0.0 0.0 0.0"/>
      <mass value="0.00001"/>
      <inertia ixx="1.0" ixy="0.0" ixz="0.0" iyy="1.0" iyz="0.0" izz="1.0"/>
    </inertial>
  </link>
  <!-- coxa -->
  <joint name="coxa_joint_LF" type="revolute">
    <origin rpy="0.0 0.0 0.785398163397" xyz="0.0 0.0 0.0"/>
    <parent link="leg_center_LF"/>
    <child link="coxa_LF"/>
    <axis xyz="0.0 0.0 1.0"/>
    <limit effort="6.0" lower="-3.14" upper="3.14" velocity="0.524"/>
  </joint>
  <transmission name="coxa_transmission_LF">
    <type>transmission_interface/SimpleTransmission</type>
    <joint name="coxa_joint_LF">
      <hardwareInterface>EffortJointInterface</hardwareInterface>
    </joint>
    <actuator name="coxa_motor_LF">
      <hardwareInterface>EffortJointInterface</hardwareInterface>
      <mechanicalReduction>1</mechanicalReduction>
    </actuator>
  </transmission>
  <link name="coxa_LF">
    <visual>
      <origin rpy="0.0 0.0 0.0" xyz="0.0 0.0 0.0"/>
      <geometry>
        <mesh filename="package://phantom_description/meshes/phantomX/coxa.stl" scale="0.001 0.001 0.001"/>
      </geometry>
      <material name="">
        <color rgba="0.7 0.7 0.7 1"/>
      </material>
    </visual>
    <collision>
      <origin rpy="0.0 0.0 0.0" xyz="0.0 0.0 0.0"/>
      <geometry>
        <mesh filename="package://phantom_description/meshes/phantomX/coxa.stl" scale="0.001 0.001 0.001"/>
      </geometry>
      <material name="">
        <color rgba="0.7 0.7 0.7 1"/>
      </material>
    </collision>
    <inertial>
      <origin rpy="0.0 0.0 0.0" xyz="0.0 0.0 0.0"/>
      <mass value="0.00001"/>
      <inertia ixx="1.0" ixy="0.0" ixz="0.0" iyy="1.0" iyz="0.0" izz="1.0"/>
    </inertial>
  </link>
  <gazebo reference="coxa_LF">
    <material>Gazebo/DarkGrey</material>
  </gazebo>
  <!-- femur -->
  <joint name="femur_joint_LF" type="revolute">
    <origin rpy="-1.57079632679 1.57079632679 0.0" xyz="0.052 0.0 0.0"/>
    <parent link="coxa_LF"/>
    <child link="femur_LF"/>
    <axis xyz="0.0 0.0 1"/>
    <limit effort="6.0" lower="-3.14" upper="3.14" velocity="0.524"/>
  </joint>
  <transmission name="femur_transmission_LF">
    <type>transmission_interface/SimpleTransmission</type>
    <joint name="femur_joint_LF">
      <hardwareInterface>EffortJointInterface</hardwareInterface>
    </joint>
    <actuator name="femur_motor_LF">
      <hardwareInterface>EffortJointInterface</hardwareInterface>
      <mechanicalReduction>1</mechanicalReduction>
    </actuator>
  </transmission>
  <link name="femur_LF">
    <visual>
      <origin rpy="0.0 0.0 0.0" xyz="0.0 0.0 0.0"/>
      <geometry>
        <mesh filename="package://phantom_description/meshes/phantomX/femur.stl" scale="0.001 0.001 0.001"/>
      </geometry>
      <material name="">
        <color rgba="0.7 0.7 0.7 1"/>
      </material>
    </visual>
    <collision>
      <origin rpy="0.0 0.0 0.0" xyz="0.0 0.0 0.0"/>
      <geometry>
        <mesh filename="package://phantom_description/meshes/phantomX/femur.stl" scale="0.001 0.001 0.001"/>
      </geometry>
      <material name="">
        <color rgba="0.7 0.7 0.7 1"/>
      </material>
    </collision>
    <inertial>
      <origin rpy="0.0 0.0 0.0" xyz="0.0 0.0 0.0"/>
      <mass value="0.00001"/>
      <inertia ixx="1.0" ixy="0.0" ixz="0.0" iyy="1.0" iyz="0.0" izz="1.0"/>
    </inertial>
  </link>
  <gazebo reference="femur_LF">
    <material>Gazebo/DarkGrey</material>
  </gazebo>
  <!-- tibia -->
  <joint name="tibia_joint_LF" type="revolute">
    <origin rpy="3.14159265359 0.0 0.0" xyz="0.0 -0.065 0.0"/>
    <parent link="femur_LF"/>
    <child link="tibia_LF"/>
    <axis xyz="0.0 0.0 -1"/>
    <limit effort="6.0" lower="-3.14" upper="3.14" velocity="0.524"/>
  </joint>
  <transmission name="tibia_transmission_LF">
    <type>transmission_interface/SimpleTransmission</type>
    <joint name="tibia_joint_LF">
      <hardwareInterface>EffortJointInterface</hardwareInterface>
    </joint>
    <actuator name="tibia_motor_LF">
      <hardwareInterface>EffortJointInterface</hardwareInterface>
      <mechanicalReduction>1</mechanicalReduction>
    </actuator>
  </transmission>
  <link name="tibia_LF">
    <visual>
      <origin rpy="0.0 0.0 0.0" xyz="0.0 0.0 0.0"/>
      <geometry>
        <mesh filename="package://phantom_description/meshes/phantomX/tibia.stl" scale="0.001 0.001 0.001"/>
      </geometry>
      <material name="">
        <color rgba="0.7 0.7 0.7 1"/>
      </material>
    </visual>
    <collision>
      <origin rpy="0.0 0.0 0.0" xyz="0.0 0.0 0.0"/>
      <geometry>
        <mesh filename="package://phantom_description/meshes/phantomX/tibia.stl" scale="0.001 0.001 0.001"/>
      </geometry>
      <material name="">
        <color rgba="0.7 0.7 0.7 1"/>
      </material>
    </collision>
    <inertial>
      <origin rpy="0.0 0.0 0.0" xyz="0.0 0.0 0.0"/>
      <mass value="0.00001"/>
      <inertia ixx="1.0" ixy="0.0" ixz="0.0" iyy="1.0" iyz="0.0" izz="1.0"/>
    </inertial>
  </link>
  <gazebo reference="tibia_LF">
    <material>Gazebo/DarkGrey</material>
  </gazebo>
</robot>
